[2022-09-16 00:19:07,630] {taskinstance.py:1159} INFO - Dependencies all met for <TaskInstance: parser_dag.parser_python scheduled__2022-09-15T00:00:00+00:00 [queued]>
[2022-09-16 00:19:07,827] {taskinstance.py:1159} INFO - Dependencies all met for <TaskInstance: parser_dag.parser_python scheduled__2022-09-15T00:00:00+00:00 [queued]>
[2022-09-16 00:19:07,835] {taskinstance.py:1356} INFO - 
--------------------------------------------------------------------------------
[2022-09-16 00:19:07,841] {taskinstance.py:1357} INFO - Starting attempt 1 of 1
[2022-09-16 00:19:07,849] {taskinstance.py:1358} INFO - 
--------------------------------------------------------------------------------
[2022-09-16 00:19:08,182] {taskinstance.py:1377} INFO - Executing <Task(PythonOperator): parser_python> on 2022-09-15 00:00:00+00:00
[2022-09-16 00:19:08,209] {standard_task_runner.py:52} INFO - Started process 46636 to run task
[2022-09-16 00:19:08,304] {standard_task_runner.py:79} INFO - Running: ['***', 'tasks', 'run', 'parser_dag', 'parser_python', 'scheduled__2022-09-15T00:00:00+00:00', '--job-id', '93', '--raw', '--subdir', 'DAGS_FOLDER/pre_parser.py', '--cfg-path', '/tmp/tmpmjusvdd2', '--error-file', '/tmp/tmpc36w99e6']
[2022-09-16 00:19:08,374] {standard_task_runner.py:80} INFO - Job 93: Subtask parser_python
[2022-09-16 00:19:09,978] {task_command.py:369} INFO - Running <TaskInstance: parser_dag.parser_python scheduled__2022-09-15T00:00:00+00:00 [running]> on host 1085bb4029c2
[2022-09-16 00:19:11,551] {taskinstance.py:1571} INFO - Exporting the following env vars:
AIRFLOW_CTX_DAG_OWNER=***
AIRFLOW_CTX_DAG_ID=parser_dag
AIRFLOW_CTX_TASK_ID=parser_python
AIRFLOW_CTX_EXECUTION_DATE=2022-09-15T00:00:00+00:00
AIRFLOW_CTX_TRY_NUMBER=1
AIRFLOW_CTX_DAG_RUN_ID=scheduled__2022-09-15T00:00:00+00:00
[2022-09-16 00:19:16,115] {taskinstance.py:1889} ERROR - Task failed with exception
Traceback (most recent call last):
  File "/home/airflow/.local/lib/python3.7/site-packages/urllib3/connectionpool.py", line 710, in urlopen
    chunked=chunked,
  File "/home/airflow/.local/lib/python3.7/site-packages/urllib3/connectionpool.py", line 386, in _make_request
    self._validate_conn(conn)
  File "/home/airflow/.local/lib/python3.7/site-packages/urllib3/connectionpool.py", line 1040, in _validate_conn
    conn.connect()
  File "/home/airflow/.local/lib/python3.7/site-packages/urllib3/connection.py", line 424, in connect
    tls_in_tls=tls_in_tls,
  File "/home/airflow/.local/lib/python3.7/site-packages/urllib3/util/ssl_.py", line 450, in ssl_wrap_socket
    sock, context, tls_in_tls, server_hostname=server_hostname
  File "/home/airflow/.local/lib/python3.7/site-packages/urllib3/util/ssl_.py", line 493, in _ssl_wrap_socket_impl
    return ssl_context.wrap_socket(sock, server_hostname=server_hostname)
  File "/usr/local/lib/python3.7/ssl.py", line 423, in wrap_socket
    session=session
  File "/usr/local/lib/python3.7/ssl.py", line 870, in _create
    self.do_handshake()
  File "/usr/local/lib/python3.7/ssl.py", line 1139, in do_handshake
    self._sslobj.do_handshake()
OSError: [Errno 0] Error

During handling of the above exception, another exception occurred:

Traceback (most recent call last):
  File "/home/airflow/.local/lib/python3.7/site-packages/requests/adapters.py", line 450, in send
    timeout=timeout
  File "/home/airflow/.local/lib/python3.7/site-packages/urllib3/connectionpool.py", line 786, in urlopen
    method, url, error=e, _pool=self, _stacktrace=sys.exc_info()[2]
  File "/home/airflow/.local/lib/python3.7/site-packages/urllib3/util/retry.py", line 550, in increment
    raise six.reraise(type(error), error, _stacktrace)
  File "/home/airflow/.local/lib/python3.7/site-packages/urllib3/packages/six.py", line 769, in reraise
    raise value.with_traceback(tb)
  File "/home/airflow/.local/lib/python3.7/site-packages/urllib3/connectionpool.py", line 710, in urlopen
    chunked=chunked,
  File "/home/airflow/.local/lib/python3.7/site-packages/urllib3/connectionpool.py", line 386, in _make_request
    self._validate_conn(conn)
  File "/home/airflow/.local/lib/python3.7/site-packages/urllib3/connectionpool.py", line 1040, in _validate_conn
    conn.connect()
  File "/home/airflow/.local/lib/python3.7/site-packages/urllib3/connection.py", line 424, in connect
    tls_in_tls=tls_in_tls,
  File "/home/airflow/.local/lib/python3.7/site-packages/urllib3/util/ssl_.py", line 450, in ssl_wrap_socket
    sock, context, tls_in_tls, server_hostname=server_hostname
  File "/home/airflow/.local/lib/python3.7/site-packages/urllib3/util/ssl_.py", line 493, in _ssl_wrap_socket_impl
    return ssl_context.wrap_socket(sock, server_hostname=server_hostname)
  File "/usr/local/lib/python3.7/ssl.py", line 423, in wrap_socket
    session=session
  File "/usr/local/lib/python3.7/ssl.py", line 870, in _create
    self.do_handshake()
  File "/usr/local/lib/python3.7/ssl.py", line 1139, in do_handshake
    self._sslobj.do_handshake()
urllib3.exceptions.ProtocolError: ('Connection aborted.', OSError(0, 'Error'))

During handling of the above exception, another exception occurred:

Traceback (most recent call last):
  File "/home/airflow/.local/lib/python3.7/site-packages/airflow/operators/python.py", line 171, in execute
    return_value = self.execute_callable()
  File "/home/airflow/.local/lib/python3.7/site-packages/airflow/operators/python.py", line 189, in execute_callable
    return self.python_callable(*self.op_args, **self.op_kwargs)
  File "/opt/airflow/dags/pre_parser.py", line 98, in final
    data = parse_shop_list(city='moskva', shop_list=shop_list, page_range=100)
  File "/opt/airflow/dags/pre_parser.py", line 85, in parse_shop_list
    shop_dict[shop] = parse_shop(city=city, shop=shop, page_range=page_range)
  File "/opt/airflow/dags/pre_parser.py", line 63, in parse_shop
    code = check_url_code(city, shop, page_num=page)
  File "/opt/airflow/dags/pre_parser.py", line 32, in check_url_code
    return requests.get(url, allow_redirects=True).status_code
  File "/home/airflow/.local/lib/python3.7/site-packages/requests/api.py", line 75, in get
    return request('get', url, params=params, **kwargs)
  File "/home/airflow/.local/lib/python3.7/site-packages/requests/api.py", line 61, in request
    return session.request(method=method, url=url, **kwargs)
  File "/home/airflow/.local/lib/python3.7/site-packages/requests/sessions.py", line 529, in request
    resp = self.send(prep, **send_kwargs)
  File "/home/airflow/.local/lib/python3.7/site-packages/requests/sessions.py", line 645, in send
    r = adapter.send(request, **kwargs)
  File "/home/airflow/.local/lib/python3.7/site-packages/requests/adapters.py", line 501, in send
    raise ConnectionError(err, request=request)
requests.exceptions.ConnectionError: ('Connection aborted.', OSError(0, 'Error'))
[2022-09-16 00:19:18,422] {taskinstance.py:1400} INFO - Marking task as FAILED. dag_id=parser_dag, task_id=parser_python, execution_date=20220915T000000, start_date=20220916T001907, end_date=20220916T001918
[2022-09-16 00:19:18,990] {standard_task_runner.py:97} ERROR - Failed to execute job 93 for task parser_python (('Connection aborted.', OSError(0, 'Error')); 46636)
[2022-09-16 00:19:24,322] {local_task_job.py:156} INFO - Task exited with return code 1
[2022-09-16 01:39:18,826] {local_task_job.py:273} INFO - 0 downstream tasks scheduled from follow-on schedule check
