[2022-09-14 14:31:08,121] {taskinstance.py:1159} INFO - Dependencies all met for <TaskInstance: parser_dag.parser_python manual__2022-09-14T14:31:06.970320+00:00 [queued]>
[2022-09-14 14:31:08,155] {taskinstance.py:1159} INFO - Dependencies all met for <TaskInstance: parser_dag.parser_python manual__2022-09-14T14:31:06.970320+00:00 [queued]>
[2022-09-14 14:31:08,160] {taskinstance.py:1356} INFO - 
--------------------------------------------------------------------------------
[2022-09-14 14:31:08,169] {taskinstance.py:1357} INFO - Starting attempt 1 of 1
[2022-09-14 14:31:08,173] {taskinstance.py:1358} INFO - 
--------------------------------------------------------------------------------
[2022-09-14 14:31:08,209] {taskinstance.py:1377} INFO - Executing <Task(PythonOperator): parser_python> on 2022-09-14 14:31:06.970320+00:00
[2022-09-14 14:31:08,217] {standard_task_runner.py:52} INFO - Started process 153 to run task
[2022-09-14 14:31:08,235] {standard_task_runner.py:79} INFO - Running: ['***', 'tasks', 'run', 'parser_dag', 'parser_python', 'manual__2022-09-14T14:31:06.970320+00:00', '--job-id', '31', '--raw', '--subdir', 'DAGS_FOLDER/pre_parser.py', '--cfg-path', '/tmp/tmpopnhuoye', '--error-file', '/tmp/tmpisf7bmh0']
[2022-09-14 14:31:08,237] {standard_task_runner.py:80} INFO - Job 31: Subtask parser_python
[2022-09-14 14:31:08,492] {task_command.py:369} INFO - Running <TaskInstance: parser_dag.parser_python manual__2022-09-14T14:31:06.970320+00:00 [running]> on host c0f73d32ee2c
[2022-09-14 14:31:08,749] {taskinstance.py:1571} INFO - Exporting the following env vars:
AIRFLOW_CTX_DAG_OWNER=***
AIRFLOW_CTX_DAG_ID=parser_dag
AIRFLOW_CTX_TASK_ID=parser_python
AIRFLOW_CTX_EXECUTION_DATE=2022-09-14T14:31:06.970320+00:00
AIRFLOW_CTX_TRY_NUMBER=1
AIRFLOW_CTX_DAG_RUN_ID=manual__2022-09-14T14:31:06.970320+00:00
[2022-09-14 14:31:08,753] {taskinstance.py:1889} ERROR - Task failed with exception
Traceback (most recent call last):
  File "/home/airflow/.local/lib/python3.7/site-packages/airflow/operators/python.py", line 171, in execute
    return_value = self.execute_callable()
  File "/home/airflow/.local/lib/python3.7/site-packages/airflow/operators/python.py", line 189, in execute_callable
    return self.python_callable(*self.op_args, **self.op_kwargs)
  File "/opt/airflow/dags/pre_parser.py", line 91, in final
    data = parse_shop_list(city='moskva', shop_list=shop_list, page_range=100)
  File "/opt/airflow/dags/pre_parser.py", line 82, in parse_shop_list
    for shop in tqdm(shop_list):
NameError: name 'tqdm' is not defined
[2022-09-14 14:31:08,778] {taskinstance.py:1400} INFO - Marking task as FAILED. dag_id=parser_dag, task_id=parser_python, execution_date=20220914T143106, start_date=20220914T143108, end_date=20220914T143108
[2022-09-14 14:31:08,800] {standard_task_runner.py:97} ERROR - Failed to execute job 31 for task parser_python (name 'tqdm' is not defined; 153)
[2022-09-14 14:31:08,886] {local_task_job.py:156} INFO - Task exited with return code 1
[2022-09-14 14:31:09,027] {local_task_job.py:273} INFO - 0 downstream tasks scheduled from follow-on schedule check
