[2022-10-16 22:50:43,330] {taskinstance.py:1159} INFO - Dependencies all met for <TaskInstance: parser_dag.parser_python scheduled__2022-10-12T00:00:00+00:00 [queued]>
[2022-10-16 22:50:43,583] {taskinstance.py:1159} INFO - Dependencies all met for <TaskInstance: parser_dag.parser_python scheduled__2022-10-12T00:00:00+00:00 [queued]>
[2022-10-16 22:50:43,599] {taskinstance.py:1356} INFO - 
--------------------------------------------------------------------------------
[2022-10-16 22:50:43,603] {taskinstance.py:1357} INFO - Starting attempt 1 of 1
[2022-10-16 22:50:43,608] {taskinstance.py:1358} INFO - 
--------------------------------------------------------------------------------
[2022-10-16 22:50:44,151] {taskinstance.py:1377} INFO - Executing <Task(PythonOperator): parser_python> on 2022-10-12 00:00:00+00:00
[2022-10-16 22:50:44,267] {standard_task_runner.py:52} INFO - Started process 117 to run task
[2022-10-16 22:50:44,345] {standard_task_runner.py:79} INFO - Running: ['***', 'tasks', 'run', 'parser_dag', 'parser_python', 'scheduled__2022-10-12T00:00:00+00:00', '--job-id', '10', '--raw', '--subdir', 'DAGS_FOLDER/pre_parser.py', '--cfg-path', '/tmp/tmp8tkvbzag', '--error-file', '/tmp/tmpznoynnoa']
[2022-10-16 22:50:44,374] {standard_task_runner.py:80} INFO - Job 10: Subtask parser_python
[2022-10-16 22:50:45,663] {task_command.py:369} INFO - Running <TaskInstance: parser_dag.parser_python scheduled__2022-10-12T00:00:00+00:00 [running]> on host eda31ed78ba3
[2022-10-16 22:50:47,056] {taskinstance.py:1571} INFO - Exporting the following env vars:
AIRFLOW_CTX_DAG_OWNER=***
AIRFLOW_CTX_DAG_ID=parser_dag
AIRFLOW_CTX_TASK_ID=parser_python
AIRFLOW_CTX_EXECUTION_DATE=2022-10-12T00:00:00+00:00
AIRFLOW_CTX_TRY_NUMBER=1
AIRFLOW_CTX_DAG_RUN_ID=scheduled__2022-10-12T00:00:00+00:00
[2022-10-16 22:50:48,167] {taskinstance.py:1889} ERROR - Task failed with exception
Traceback (most recent call last):
  File "/home/airflow/.local/lib/python3.7/site-packages/urllib3/connection.py", line 175, in _new_conn
    (self._dns_host, self.port), self.timeout, **extra_kw
  File "/home/airflow/.local/lib/python3.7/site-packages/urllib3/util/connection.py", line 95, in create_connection
    raise err
  File "/home/airflow/.local/lib/python3.7/site-packages/urllib3/util/connection.py", line 85, in create_connection
    sock.connect(sa)
ConnectionRefusedError: [Errno 111] Connection refused

During handling of the above exception, another exception occurred:

Traceback (most recent call last):
  File "/home/airflow/.local/lib/python3.7/site-packages/urllib3/connectionpool.py", line 710, in urlopen
    chunked=chunked,
  File "/home/airflow/.local/lib/python3.7/site-packages/urllib3/connectionpool.py", line 386, in _make_request
    self._validate_conn(conn)
  File "/home/airflow/.local/lib/python3.7/site-packages/urllib3/connectionpool.py", line 1040, in _validate_conn
    conn.connect()
  File "/home/airflow/.local/lib/python3.7/site-packages/urllib3/connection.py", line 358, in connect
    self.sock = conn = self._new_conn()
  File "/home/airflow/.local/lib/python3.7/site-packages/urllib3/connection.py", line 187, in _new_conn
    self, "Failed to establish a new connection: %s" % e
urllib3.exceptions.NewConnectionError: <urllib3.connection.HTTPSConnection object at 0xffff7de38d50>: Failed to establish a new connection: [Errno 111] Connection refused

During handling of the above exception, another exception occurred:

Traceback (most recent call last):
  File "/home/airflow/.local/lib/python3.7/site-packages/requests/adapters.py", line 450, in send
    timeout=timeout
  File "/home/airflow/.local/lib/python3.7/site-packages/urllib3/connectionpool.py", line 786, in urlopen
    method, url, error=e, _pool=self, _stacktrace=sys.exc_info()[2]
  File "/home/airflow/.local/lib/python3.7/site-packages/urllib3/util/retry.py", line 592, in increment
    raise MaxRetryError(_pool, url, error or ResponseError(cause))
urllib3.exceptions.MaxRetryError: HTTPSConnectionPool(host='squark.edadeal.ru', port=443): Max retries exceeded with url: /web/search/offers?count=50&locality=moskva&page=1&retailer=5ka (Caused by NewConnectionError('<urllib3.connection.HTTPSConnection object at 0xffff7de38d50>: Failed to establish a new connection: [Errno 111] Connection refused'))

During handling of the above exception, another exception occurred:

Traceback (most recent call last):
  File "/home/airflow/.local/lib/python3.7/site-packages/airflow/operators/python.py", line 171, in execute
    return_value = self.execute_callable()
  File "/home/airflow/.local/lib/python3.7/site-packages/airflow/operators/python.py", line 189, in execute_callable
    return self.python_callable(*self.op_args, **self.op_kwargs)
  File "/opt/airflow/dags/pre_parser.py", line 100, in final
    data = parse_shop_list(city='moskva', shop_list=shop_list, page_range=100)
  File "/opt/airflow/dags/pre_parser.py", line 87, in parse_shop_list
    shop_dict[shop] = parse_shop(city=city, shop=shop, page_range=page_range)
  File "/opt/airflow/dags/pre_parser.py", line 67, in parse_shop
    data = parse_page(city, shop, page_num=page)
  File "/opt/airflow/dags/pre_parser.py", line 46, in parse_page
    data = requests.get(url, allow_redirects=True)  # data.content is a protobuf message
  File "/home/airflow/.local/lib/python3.7/site-packages/requests/api.py", line 75, in get
    return request('get', url, params=params, **kwargs)
  File "/home/airflow/.local/lib/python3.7/site-packages/requests/api.py", line 61, in request
    return session.request(method=method, url=url, **kwargs)
  File "/home/airflow/.local/lib/python3.7/site-packages/requests/sessions.py", line 529, in request
    resp = self.send(prep, **send_kwargs)
  File "/home/airflow/.local/lib/python3.7/site-packages/requests/sessions.py", line 645, in send
    r = adapter.send(request, **kwargs)
  File "/home/airflow/.local/lib/python3.7/site-packages/requests/adapters.py", line 519, in send
    raise ConnectionError(e, request=request)
requests.exceptions.ConnectionError: HTTPSConnectionPool(host='squark.edadeal.ru', port=443): Max retries exceeded with url: /web/search/offers?count=50&locality=moskva&page=1&retailer=5ka (Caused by NewConnectionError('<urllib3.connection.HTTPSConnection object at 0xffff7de38d50>: Failed to establish a new connection: [Errno 111] Connection refused'))
[2022-10-16 22:50:48,305] {taskinstance.py:1400} INFO - Marking task as FAILED. dag_id=parser_dag, task_id=parser_python, execution_date=20221012T000000, start_date=20221016T225043, end_date=20221016T225048
[2022-10-16 22:50:48,399] {standard_task_runner.py:97} ERROR - Failed to execute job 10 for task parser_python (HTTPSConnectionPool(host='squark.edadeal.ru', port=443): Max retries exceeded with url: /web/search/offers?count=50&locality=moskva&page=1&retailer=5ka (Caused by NewConnectionError('<urllib3.connection.HTTPSConnection object at 0xffff7de38d50>: Failed to establish a new connection: [Errno 111] Connection refused')); 117)
[2022-10-16 22:50:48,602] {local_task_job.py:156} INFO - Task exited with return code 1
[2022-10-16 22:50:48,943] {local_task_job.py:273} INFO - 0 downstream tasks scheduled from follow-on schedule check
