[2022-09-14 15:21:25,089] {taskinstance.py:1159} INFO - Dependencies all met for <TaskInstance: 3_download_rocket_launches.download_rocket_launches scheduled__2022-09-11T00:00:00+00:00 [queued]>
[2022-09-14 15:21:25,102] {taskinstance.py:1159} INFO - Dependencies all met for <TaskInstance: 3_download_rocket_launches.download_rocket_launches scheduled__2022-09-11T00:00:00+00:00 [queued]>
[2022-09-14 15:21:25,103] {taskinstance.py:1356} INFO - 
--------------------------------------------------------------------------------
[2022-09-14 15:21:25,104] {taskinstance.py:1357} INFO - Starting attempt 1 of 1
[2022-09-14 15:21:25,105] {taskinstance.py:1358} INFO - 
--------------------------------------------------------------------------------
[2022-09-14 15:21:25,124] {taskinstance.py:1377} INFO - Executing <Task(PythonOperator): download_rocket_launches> on 2022-09-11 00:00:00+00:00
[2022-09-14 15:21:25,134] {standard_task_runner.py:52} INFO - Started process 2656 to run task
[2022-09-14 15:21:25,146] {standard_task_runner.py:79} INFO - Running: ['***', 'tasks', 'run', '3_download_rocket_launches', 'download_rocket_launches', 'scheduled__2022-09-11T00:00:00+00:00', '--job-id', '52', '--raw', '--subdir', 'DAGS_FOLDER/test_test.py', '--cfg-path', '/tmp/tmpf97gb3x0', '--error-file', '/tmp/tmphxrzn82u']
[2022-09-14 15:21:25,148] {standard_task_runner.py:80} INFO - Job 52: Subtask download_rocket_launches
[2022-09-14 15:21:25,237] {task_command.py:369} INFO - Running <TaskInstance: 3_download_rocket_launches.download_rocket_launches scheduled__2022-09-11T00:00:00+00:00 [running]> on host c0f73d32ee2c
[2022-09-14 15:21:25,350] {taskinstance.py:1571} INFO - Exporting the following env vars:
AIRFLOW_CTX_DAG_OWNER=***
AIRFLOW_CTX_DAG_ID=3_download_rocket_launches
AIRFLOW_CTX_TASK_ID=download_rocket_launches
AIRFLOW_CTX_EXECUTION_DATE=2022-09-11T00:00:00+00:00
AIRFLOW_CTX_TRY_NUMBER=1
AIRFLOW_CTX_DAG_RUN_ID=scheduled__2022-09-11T00:00:00+00:00
[2022-09-14 15:21:25,353] {warnings.py:110} WARNING - /home/***/.local/lib/python3.7/site-packages/***/utils/context.py:290: AirflowContextDeprecationWarning: Accessing 'tomorrow_ds' from the template is deprecated and will be removed in a future version.
  warnings.warn(_create_deprecation_warning(k, replacements))

[2022-09-14 15:21:25,355] {taskinstance.py:1889} ERROR - Task failed with exception
Traceback (most recent call last):
  File "/usr/local/lib/python3.7/pathlib.py", line 1273, in mkdir
    self._accessor.mkdir(self, mode)
FileNotFoundError: [Errno 2] No such file or directory: '/data/rocket_launches/ds=2022-09-11'

During handling of the above exception, another exception occurred:

Traceback (most recent call last):
  File "/usr/local/lib/python3.7/pathlib.py", line 1273, in mkdir
    self._accessor.mkdir(self, mode)
FileNotFoundError: [Errno 2] No such file or directory: '/data/rocket_launches'

During handling of the above exception, another exception occurred:

Traceback (most recent call last):
  File "/home/airflow/.local/lib/python3.7/site-packages/airflow/operators/python.py", line 171, in execute
    return_value = self.execute_callable()
  File "/home/airflow/.local/lib/python3.7/site-packages/airflow/operators/python.py", line 189, in execute_callable
    return self.python_callable(*self.op_args, **self.op_kwargs)
  File "/opt/airflow/dags/test_test.py", line 35, in _download_rocket_launches
    pathlib.Path(result_path).mkdir(parents=True, exist_ok=True)
  File "/usr/local/lib/python3.7/pathlib.py", line 1277, in mkdir
    self.parent.mkdir(parents=True, exist_ok=True)
  File "/usr/local/lib/python3.7/pathlib.py", line 1277, in mkdir
    self.parent.mkdir(parents=True, exist_ok=True)
  File "/usr/local/lib/python3.7/pathlib.py", line 1273, in mkdir
    self._accessor.mkdir(self, mode)
PermissionError: [Errno 13] Permission denied: '/data'
[2022-09-14 15:21:25,370] {taskinstance.py:1400} INFO - Marking task as FAILED. dag_id=3_download_rocket_launches, task_id=download_rocket_launches, execution_date=20220911T000000, start_date=20220914T152125, end_date=20220914T152125
[2022-09-14 15:21:25,388] {standard_task_runner.py:97} ERROR - Failed to execute job 52 for task download_rocket_launches ([Errno 13] Permission denied: '/data'; 2656)
[2022-09-14 15:21:25,437] {local_task_job.py:156} INFO - Task exited with return code 1
[2022-09-14 15:21:25,501] {local_task_job.py:273} INFO - 0 downstream tasks scheduled from follow-on schedule check
