[2022-09-14 15:53:36,181] {taskinstance.py:1159} INFO - Dependencies all met for <TaskInstance: 3_download_rocket_launches.print_stats manual__2022-09-14T15:48:23.947717+00:00 [queued]>
[2022-09-14 15:53:36,187] {taskinstance.py:1159} INFO - Dependencies all met for <TaskInstance: 3_download_rocket_launches.print_stats manual__2022-09-14T15:48:23.947717+00:00 [queued]>
[2022-09-14 15:53:36,187] {taskinstance.py:1356} INFO - 
--------------------------------------------------------------------------------
[2022-09-14 15:53:36,188] {taskinstance.py:1357} INFO - Starting attempt 2 of 2
[2022-09-14 15:53:36,189] {taskinstance.py:1358} INFO - 
--------------------------------------------------------------------------------
[2022-09-14 15:53:36,198] {taskinstance.py:1377} INFO - Executing <Task(PythonOperator): print_stats> on 2022-09-14 15:48:23.947717+00:00
[2022-09-14 15:53:36,203] {standard_task_runner.py:52} INFO - Started process 617 to run task
[2022-09-14 15:53:36,206] {standard_task_runner.py:79} INFO - Running: ['***', 'tasks', 'run', '3_download_rocket_launches', 'print_stats', 'manual__2022-09-14T15:48:23.947717+00:00', '--job-id', '70', '--raw', '--subdir', 'DAGS_FOLDER/test_test.py', '--cfg-path', '/tmp/tmppkxe9ce0', '--error-file', '/tmp/tmp8exk03z8']
[2022-09-14 15:53:36,208] {standard_task_runner.py:80} INFO - Job 70: Subtask print_stats
[2022-09-14 15:53:36,247] {task_command.py:369} INFO - Running <TaskInstance: 3_download_rocket_launches.print_stats manual__2022-09-14T15:48:23.947717+00:00 [running]> on host 0895a10dcb58
[2022-09-14 15:53:36,288] {taskinstance.py:1571} INFO - Exporting the following env vars:
AIRFLOW_CTX_DAG_OWNER=***
AIRFLOW_CTX_DAG_ID=3_download_rocket_launches
AIRFLOW_CTX_TASK_ID=print_stats
AIRFLOW_CTX_EXECUTION_DATE=2022-09-14T15:48:23.947717+00:00
AIRFLOW_CTX_TRY_NUMBER=2
AIRFLOW_CTX_DAG_RUN_ID=manual__2022-09-14T15:48:23.947717+00:00
[2022-09-14 15:53:36,290] {taskinstance.py:1889} ERROR - Task failed with exception
Traceback (most recent call last):
  File "/home/airflow/.local/lib/python3.7/site-packages/airflow/operators/python.py", line 171, in execute
    return_value = self.execute_callable()
  File "/home/airflow/.local/lib/python3.7/site-packages/airflow/operators/python.py", line 189, in execute_callable
    return self.python_callable(*self.op_args, **self.op_kwargs)
  File "/opt/airflow/dags/test_test.py", line 43, in _print_stats
    with open(f"dags/data/rocket_launches/ds={ds}/launches.json") as f:
FileNotFoundError: [Errno 2] No such file or directory: 'dags/data/rocket_launches/ds=2022-09-14/launches.json'
[2022-09-14 15:53:36,299] {taskinstance.py:1400} INFO - Marking task as FAILED. dag_id=3_download_rocket_launches, task_id=print_stats, execution_date=20220914T154823, start_date=20220914T155336, end_date=20220914T155336
[2022-09-14 15:53:36,305] {standard_task_runner.py:97} ERROR - Failed to execute job 70 for task print_stats ([Errno 2] No such file or directory: 'dags/data/rocket_launches/ds=2022-09-14/launches.json'; 617)
[2022-09-14 15:53:36,342] {local_task_job.py:156} INFO - Task exited with return code 1
[2022-09-14 15:53:36,361] {local_task_job.py:273} INFO - 0 downstream tasks scheduled from follow-on schedule check
