[2022-09-14 15:55:02,474] {taskinstance.py:1159} INFO - Dependencies all met for <TaskInstance: 3_download_rocket_launches.print_stats manual__2022-09-14T15:48:23.947717+00:00 [queued]>
[2022-09-14 15:55:02,481] {taskinstance.py:1159} INFO - Dependencies all met for <TaskInstance: 3_download_rocket_launches.print_stats manual__2022-09-14T15:48:23.947717+00:00 [queued]>
[2022-09-14 15:55:02,483] {taskinstance.py:1356} INFO - 
--------------------------------------------------------------------------------
[2022-09-14 15:55:02,484] {taskinstance.py:1357} INFO - Starting attempt 3 of 3
[2022-09-14 15:55:02,485] {taskinstance.py:1358} INFO - 
--------------------------------------------------------------------------------
[2022-09-14 15:55:02,495] {taskinstance.py:1377} INFO - Executing <Task(PythonOperator): print_stats> on 2022-09-14 15:48:23.947717+00:00
[2022-09-14 15:55:02,500] {standard_task_runner.py:52} INFO - Started process 693 to run task
[2022-09-14 15:55:02,507] {standard_task_runner.py:79} INFO - Running: ['***', 'tasks', 'run', '3_download_rocket_launches', 'print_stats', 'manual__2022-09-14T15:48:23.947717+00:00', '--job-id', '72', '--raw', '--subdir', 'DAGS_FOLDER/test_test.py', '--cfg-path', '/tmp/tmphb086d7w', '--error-file', '/tmp/tmpa0sqvsm_']
[2022-09-14 15:55:02,509] {standard_task_runner.py:80} INFO - Job 72: Subtask print_stats
[2022-09-14 15:55:02,559] {task_command.py:369} INFO - Running <TaskInstance: 3_download_rocket_launches.print_stats manual__2022-09-14T15:48:23.947717+00:00 [running]> on host 0895a10dcb58
[2022-09-14 15:55:02,612] {taskinstance.py:1571} INFO - Exporting the following env vars:
AIRFLOW_CTX_DAG_OWNER=***
AIRFLOW_CTX_DAG_ID=3_download_rocket_launches
AIRFLOW_CTX_TASK_ID=print_stats
AIRFLOW_CTX_EXECUTION_DATE=2022-09-14T15:48:23.947717+00:00
AIRFLOW_CTX_TRY_NUMBER=3
AIRFLOW_CTX_DAG_RUN_ID=manual__2022-09-14T15:48:23.947717+00:00
[2022-09-14 15:55:02,618] {taskinstance.py:1889} ERROR - Task failed with exception
Traceback (most recent call last):
  File "/home/airflow/.local/lib/python3.7/site-packages/airflow/operators/python.py", line 171, in execute
    return_value = self.execute_callable()
  File "/home/airflow/.local/lib/python3.7/site-packages/airflow/operators/python.py", line 189, in execute_callable
    return self.python_callable(*self.op_args, **self.op_kwargs)
  File "/opt/airflow/dags/test_test.py", line 43, in _print_stats
    with open(f"dags/data/rocket_launches/ds={ds}/launches.json") as f:
IsADirectoryError: [Errno 21] Is a directory: 'dags/data/rocket_launches/ds=2022-09-14/launches.json'
[2022-09-14 15:55:02,627] {taskinstance.py:1400} INFO - Marking task as FAILED. dag_id=3_download_rocket_launches, task_id=print_stats, execution_date=20220914T154823, start_date=20220914T155502, end_date=20220914T155502
[2022-09-14 15:55:02,635] {standard_task_runner.py:97} ERROR - Failed to execute job 72 for task print_stats ([Errno 21] Is a directory: 'dags/data/rocket_launches/ds=2022-09-14/launches.json'; 693)
[2022-09-14 15:55:02,682] {local_task_job.py:156} INFO - Task exited with return code 1
[2022-09-14 15:55:02,711] {local_task_job.py:273} INFO - 0 downstream tasks scheduled from follow-on schedule check
